START 2024-10-31 10:53:32
SLURM_JOB_ID=13248170
SLURM_JOB_NUM_NODES=1
SLURM_NODELIST=jrc0288
The following modules were not unloaded:
  (Use "module --force purge" to unload all):

  1) Stages/2024
/usr/bin/rm: cannot remove '/usr/local/cuda/compat/lib': Read-only file system
rm: cannot remove '/usr/local/cuda/compat/lib': Read-only file system
rm: cannot remove '/usr/local/cuda/compat/lib': Read-only file system
[W1031 10:53:56.516481757 socket.cpp:518] [c10d] The server socket cannot be initialized on [::]:25678 (errno: 97 - Address family not supported by protocol).
[W1031 10:53:56.533498074 socket.cpp:752] [c10d] The client socket cannot be initialized to connect to [jrc0288i.jureca]:25678 (errno: 97 - Address family not supported by protocol).
/usr/bin/python: can't open file '/workspace/atmorep/results/output_13248170.txt': [Errno 2] No such file or directory
/usr/bin/python: can't open file '/workspace/atmorep/results/output_13248170.txt': [Errno 2] No such file or directory
/usr/bin/python: can't open file '/workspace/atmorep/results/output_13248170.txt': [Errno 2] No such file or directory
/usr/bin/python: can't open file '/workspace/atmorep/results/output_13248170.txt': [Errno 2] No such file or directory
E1031 10:53:56.493000 3429 torch/distributed/elastic/multiprocessing/api.py:863] failed (exitcode: 2) local_rank: 0 (pid: 3644) of binary: /usr/bin/python
Traceback (most recent call last):
  File "/usr/lib/python3.10/runpy.py", line 196, in _run_module_as_main
    return _run_code(code, main_globals, None,
  File "/usr/lib/python3.10/runpy.py", line 86, in _run_code
    exec(code, run_globals)
  File "/usr/local/lib/python3.10/dist-packages/torchrun_jsc/__main__.py", line 4, in <module>
    main()
  File "/usr/local/lib/python3.10/dist-packages/torchrun_jsc/__init__.py", line 38, in main
    run_main_old()
  File "/usr/local/lib/python3.10/dist-packages/torchrun_jsc/run_old.py", line 142, in main
    runpy.run_module('torch.distributed.run', run_name='__main__')
  File "/usr/lib/python3.10/runpy.py", line 227, in run_module
    return _run_code(code, {}, init_globals, run_name, mod_spec)
  File "/usr/lib/python3.10/runpy.py", line 86, in _run_code
    exec(code, run_globals)
  File "/usr/local/lib/python3.10/dist-packages/torch/distributed/run.py", line 923, in <module>
    main()
  File "/usr/local/lib/python3.10/dist-packages/torch/distributed/elastic/multiprocessing/errors/__init__.py", line 355, in wrapper
    return f(*args, **kwargs)
  File "/usr/local/lib/python3.10/dist-packages/torch/distributed/run.py", line 919, in main
    run(args)
  File "/usr/local/lib/python3.10/dist-packages/torch/distributed/run.py", line 910, in run
    elastic_launch(
  File "/usr/local/lib/python3.10/dist-packages/torch/distributed/launcher/api.py", line 138, in __call__
    return launch_agent(self._config, self._entrypoint, list(args))
  File "/usr/local/lib/python3.10/dist-packages/torch/distributed/launcher/api.py", line 269, in launch_agent
    raise ChildFailedError(
torch.distributed.elastic.multiprocessing.errors.ChildFailedError: 
============================================================
/workspace/atmorep/results/output_13248170.txt FAILED
------------------------------------------------------------
Failures:
[1]:
  time      : 2024-10-31_10:53:56
  host      : jrc0288.jureca
  rank      : 1 (local_rank: 1)
  exitcode  : 2 (pid: 3645)
  error_file: <N/A>
  traceback : To enable traceback see: https://pytorch.org/docs/stable/elastic/errors.html
[2]:
  time      : 2024-10-31_10:53:56
  host      : jrc0288.jureca
  rank      : 2 (local_rank: 2)
  exitcode  : 2 (pid: 3646)
  error_file: <N/A>
  traceback : To enable traceback see: https://pytorch.org/docs/stable/elastic/errors.html
[3]:
  time      : 2024-10-31_10:53:56
  host      : jrc0288.jureca
  rank      : 3 (local_rank: 3)
  exitcode  : 2 (pid: 3647)
  error_file: <N/A>
  traceback : To enable traceback see: https://pytorch.org/docs/stable/elastic/errors.html
------------------------------------------------------------
Root Cause (first observed failure):
[0]:
  time      : 2024-10-31_10:53:56
  host      : jrc0288.jureca
  rank      : 0 (local_rank: 0)
  exitcode  : 2 (pid: 3644)
  error_file: <N/A>
  traceback : To enable traceback see: https://pytorch.org/docs/stable/elastic/errors.html
============================================================
srun: error: jrc0288: task 0: Exited with exit code 1
